<mujoco model="iiwa_with_robotiq">
  <compiler angle="radian" meshdir="assets" autolimits="true"/>
  <option timestep="0.0005" integrator="implicitfast"/>

  <default>
    <!-- IIWA defaults -->
    <default class="iiwa">
      <material specular="0.5" shininess="0.25"/>
      <joint axis="0 0 1" damping="10"/>
      <general gaintype="fixed" biastype="affine" gainprm="2000" biasprm="0 -2000 -200"/>
      <default class="joint1">
        <joint range="-2.96706 2.96706"/>
        <general ctrlrange="-2.96706 2.96706"/>
        <default class="joint2">
          <joint range="-2.0944 2.0944"/>
          <general ctrlrange="-2.0944 2.0944"/>
        </default>
      </default>
      <default class="joint3">
        <joint range="-3.05433 3.05433"/>
        <general ctrlrange="-3.05433 3.05433"/>
      </default>
      <default class="iiwa_visual">
        <geom type="mesh" contype="0" conaffinity="0" group="2" material="gray"/>
      </default>
      <default class="iiwa_collision">
        <geom group="3"/>
      </default>
      <site size="0.001" rgba="1 0 0 1" group="4"/>
    </default>

    <!-- Robotiq defaults -->
    <default class="robotiq">
      <joint damping="2.0" armature="0.1" frictionloss="0.05"
             limited="true" solreflimit="0.005 1" solimplimit="0.99 0.999 0.001"/>
      <position kp="10" kv="0.5" forcerange="-20 20"/>
      <geom solref="0.01 1" solimp="0.95 0.99 0.001" friction="1.0 0.05 0.001"/>
      <default class="robotiq_visual">
        <geom contype="0" conaffinity="0" group="2" density="0" rgba="0.2 0.2 0.2 1"/>
      </default>
      <default class="robotiq_fingertip">
        <geom group="3" rgba="0.8 0.3 0.3 0.5" friction="2.0 0.1 0.001"/>
      </default>
    </default>
  </default>

  <asset>
    <!-- IIWA materials & meshes -->
    <material class="iiwa" name="gray" rgba="0.4 0.4 0.4 1"/>
    <material class="iiwa" name="light_gray" rgba="0.6 0.6 0.6 1"/>
    <material class="iiwa" name="black" rgba="0 0 0 1"/>
    <material class="iiwa" name="orange" rgba="1 0.423529 0.0392157 1"/>

    <mesh file="link_0.obj"/>
    <mesh file="link_1.obj"/>
    <mesh file="link_2_orange.obj"/>
    <mesh file="link_2_grey.obj"/>
    <mesh file="link_3.obj"/>
    <mesh file="band.obj"/>
    <mesh file="kuka.obj"/>
    <mesh file="link_4_orange.obj"/>
    <mesh file="link_4_grey.obj"/>
    <mesh file="link_5.obj"/>
    <mesh file="link_6_orange.obj"/>
    <mesh file="link_6_grey.obj"/>
    <mesh file="link_7.obj"/>

    <!-- Robotiq meshes (adjust paths to where you moved them) -->
    <mesh name="rq_link_0" file="robotiq/robotiq-3f-gripper_articulated/visual/link_0.obj"/>
    <mesh name="rq_link_1" file="robotiq/robotiq-3f-gripper_articulated/visual/link_1.obj"/>
    <mesh name="rq_link_2" file="robotiq/robotiq-3f-gripper_articulated/visual/link_2.obj"/>
    <mesh name="rq_link_3" file="robotiq/robotiq-3f-gripper_articulated/visual/link_3.obj"/>
    <mesh name="rq_palm"   file="robotiq/robotiq-3f-gripper_articulated/visual/palm.obj"/>

    <!-- Scene -->
    <texture type="skybox" builtin="gradient" rgb1="0.3 0.5 0.7" rgb2="0 0 0" width="512" height="3072"/>
    <texture type="2d" name="groundplane" builtin="checker" mark="edge"
             rgb1="0.2 0.3 0.4" rgb2="0.1 0.2 0.3" markrgb="0.8 0.8 0.8" width="300" height="300"/>
    <material name="groundplane" texture="groundplane" texuniform="true" texrepeat="5 5" reflectance="0.2"/>
  </asset>

  <statistic center="0.3 0 0.4" extent="1.5"/>

  <visual>
    <headlight diffuse="0.6 0.6 0.6" ambient="0.3 0.3 0.3" specular="0 0 0"/>
    <rgba haze="0.15 0.25 0.35 1"/>
    <global azimuth="-120" elevation="-20"/>
  </visual>

  <worldbody>
    <light pos="0 0 1.5" dir="0 0 -1" directional="true"/>
    <geom name="floor" size="0 0 0.05" type="plane" material="groundplane"/>
    <light name="top" pos="0 0 2" mode="trackcom"/>

    <body name="base" childclass="iiwa">
      <inertial mass="5" pos="-0.1 0 0.07" diaginertia="0.05 0.06 0.03"/>
      <geom class="iiwa_visual" mesh="link_0"/>
      <geom class="iiwa_collision" size="0.12" pos="0 0 0.03"/>
      <geom class="iiwa_collision" size="0.08" pos="-0.08 0 0.103"/>
      <geom class="iiwa_collision" size="0.08" pos="-0.08 0 0.04"/>
      <geom class="iiwa_collision" size="0.1" pos="0 0 0.14"/>
      <body name="link1" pos="0 0 0.1575">
        <inertial mass="5.76" pos="0 -0.03 0.12" diaginertia="0.0333 0.033 0.0123"/>
        <joint name="joint1" class="joint1"/>
        <geom class="iiwa_visual" mesh="link_1"/>
        <geom class="iiwa_collision" size="0.08" pos="0 0 -0.0005"/>
        <geom class="iiwa_collision" size="0.075" pos="0.01 -0.025 0.0425"/>
        <geom class="iiwa_collision" size="0.075" pos="-0.01 -0.025 0.0425"/>
        <geom class="iiwa_collision" size="0.07" pos="0.01 -0.045 0.1025"/>
        <geom class="iiwa_collision" size="0.07" pos="-0.01 -0.045 0.1025"/>
        <body name="link2" pos="0 0 0.2025" quat="0 0 1 1">
          <inertial mass="6.35" pos="0.0003 0.059 0.042" diaginertia="0.0305 0.0304 0.011" quat="0 0 1 1"/>
          <joint name="joint2" class="joint2"/>
          <geom class="iiwa_visual" material="orange" mesh="link_2_orange"/>
          <geom class="iiwa_visual" mesh="link_2_grey"/>
          <geom class="iiwa_collision" size="0.095" pos="0 0 -0.01"/>
          <geom class="iiwa_collision" size="0.09" pos="0 0 0.045"/>
          <geom class="iiwa_collision" size="0.07" pos="-0.01 0.04 0.054"/>
          <geom class="iiwa_collision" size="0.065" pos="-0.01 0.09 0.04"/>
          <geom class="iiwa_collision" size="0.065" pos="-0.01 0.13 0.02"/>
          <geom class="iiwa_collision" size="0.07" pos="0.01 0.04 0.054"/>
          <geom class="iiwa_collision" size="0.065" pos="0.01 0.09 0.04"/>
          <geom class="iiwa_collision" size="0.065" pos="0.01 0.13 0.02"/>
          <geom class="iiwa_collision" size="0.075" pos="0 0.18 0"/>
          <body name="link3" pos="0 0.2045 0" quat="0 0 1 1">
            <inertial mass="3.5" pos="0 0.03 0.13" diaginertia="0.025 0.0238 0.0076"/>
            <joint name="joint3" class="joint1"/>
            <geom class="iiwa_visual" mesh="link_3"/>
            <geom class="iiwa_visual" material="light_gray" mesh="band"/>
            <geom class="iiwa_visual" material="black" mesh="kuka"/>
            <geom class="iiwa_collision" size="0.075" pos="0 0 0.0355"/>
            <geom class="iiwa_collision" size="0.06" pos="0.01 0.023 0.0855"/>
            <geom class="iiwa_collision" size="0.055" pos="0.01 0.048 0.1255"/>
            <geom class="iiwa_collision" size="0.06" pos="0.01 0.056 0.1755"/>
            <geom class="iiwa_collision" size="0.06" pos="-0.01 0.023 0.0855"/>
            <geom class="iiwa_collision" size="0.055" pos="-0.01 0.048 0.1255"/>
            <geom class="iiwa_collision" size="0.06" pos="-0.01 0.056 0.1755"/>
            <geom class="iiwa_collision" size="0.075" pos="0 0.045 0.2155"/>
            <geom class="iiwa_collision" size="0.075" pos="0 0 0.2155"/>
            <body name="link4" pos="0 0 0.2155" quat="1 1 0 0">
              <inertial mass="3.5" pos="0 0.067 0.034" diaginertia="0.017 0.0164 0.006" quat="1 1 0 0"/>
              <joint name="joint4" class="joint2"/>
              <geom class="iiwa_visual" material="orange" mesh="link_4_orange"/>
              <geom class="iiwa_visual" mesh="link_4_grey"/>
              <geom class="iiwa_collision" size="0.078" pos="0 0.01 0.046"/>
              <geom class="iiwa_collision" size="0.06" pos="0.01 0.06 0.052"/>
              <geom class="iiwa_collision" size="0.065" pos="0.01 0.12 0.034"/>
              <geom class="iiwa_collision" size="0.06" pos="-0.01 0.06 0.052"/>
              <geom class="iiwa_collision" size="0.065" pos="-0.01 0.12 0.034"/>
              <geom class="iiwa_collision" size="0.075" pos="0 0.184 0"/>
              <body name="link5" pos="0 0.1845 0" quat="0 0 1 1">
                <inertial mass="3.5" pos="0.0001 0.021 0.076" diaginertia="0.01 0.0087 0.00449"/>
                <joint name="joint5" class="joint1"/>
                <geom class="iiwa_visual" mesh="link_5"/>
                <geom class="iiwa_visual" material="light_gray" mesh="band"/>
                <geom class="iiwa_visual" material="black" mesh="kuka"/>
                <geom class="iiwa_collision" size="0.075" pos="0 0 0.0335"/>
                <geom class="iiwa_collision" size="0.05" pos="-0.012 0.031 0.0755"/>
                <geom class="iiwa_collision" size="0.05" pos="0.012 0.031 0.0755"/>
                <geom class="iiwa_collision" size="0.04" pos="-0.012 0.06 0.1155"/>
                <geom class="iiwa_collision" size="0.04" pos="0.012 0.06 0.1155"/>
                <geom class="iiwa_collision" size="0.04" pos="-0.01 0.065 0.1655"/>
                <geom class="iiwa_collision" size="0.04" pos="0.01 0.065 0.1655"/>
                <geom class="iiwa_collision" size="0.035" pos="-0.012 0.065 0.1855"/>
                <geom class="iiwa_collision" size="0.035" pos="0.012 0.065 0.1855"/>
                <body name="link6" pos="0 0 0.2155" quat="1 1 0 0">
                  <inertial mass="1.8" pos="0 0.0006 0.0004" diaginertia="0.0049 0.0047 0.0036" quat="1 1 0 0"/>
                  <joint name="joint6" class="joint2"/>
                  <geom class="iiwa_visual" material="orange" mesh="link_6_orange"/>
                  <geom class="iiwa_visual" mesh="link_6_grey"/>
                  <geom class="iiwa_collision" size="0.055" pos="0 0 -0.059"/>
                  <geom class="iiwa_collision" size="0.065" pos="0 -0.03 0.011"/>
                  <geom class="iiwa_collision" size="0.08"/>
                  <body name="link7" pos="0 0.081 0" quat="0 0 1 1">
                    <inertial mass="1.2" pos="0 0 0.02" diaginertia="0.001 0.001 0.001"/>
                    <joint name="joint7" class="joint3"/>
                    <geom class="iiwa_visual" mesh="link_7"/>
                    <geom class="iiwa_collision" size="0.06" pos="0 0 0.001"/>
                    <site pos="0 0 0.045" name="attachment_site"/>

                    <!-- ===== GRIPPER NESTED HERE ===== -->
                    <body name="palm" pos="0 0 0.11" quat="0.7071 0.7071 0 0" childclass="robotiq">
                      <inertial pos="0 0 0" mass="1.3" diaginertia="1.5e-3 1.5e-3 1.5e-3"/>
                      <geom class="robotiq_visual" type="mesh" mesh="rq_palm"/>

                      <body name="finger_1_link_0" pos="-0.0455 0.0214 0.036" quat="-2.59838e-06 0.706825 0.707388 2.59631e-06">
                        <inertial pos="0.02 0 0" mass="0.05" diaginertia="3.3e-6 3.3e-6 3.3e-6"/>
                        <joint name="palm_finger_1_joint" axis="0 1 0" range="-0.1784 0.192"/>
                        <geom class="robotiq_visual" pos="0.02 0 0" type="mesh" mesh="rq_link_0"/>
                        <body name="finger_1_link_1" pos="0.02 0 0">
                          <inertial pos="0.025 -0.014 0" mass="0.15" diaginertia="1.0e-5 3.6e-5 3.6e-5"/>
                          <joint name="finger_1_joint_1" axis="0 0 1" range="0.0495 1.2218"/>
                          <geom class="robotiq_visual" pos="0.05 -0.028 0" quat="0.96639 0 0 -0.257081" type="mesh" mesh="rq_link_1"/>
                          <body name="finger_1_link_2" pos="0.05 -0.028 0" quat="0.96639 0 0 -0.257081">
                            <inertial pos="0.02 0 0.0075" mass="0.15" diaginertia="1.0e-5 3.6e-5 3.6e-5"/>
                            <joint name="finger_1_joint_2" axis="0 0 1" range="0 1.5708"/>
                            <geom class="robotiq_visual" pos="0.039 0 0.0075" type="mesh" mesh="rq_link_2"/>
                            <body name="finger_1_link_3" pos="0.039 0 0">
                              <inertial pos="0.01 0 0" mass="0.05" diaginertia="3.3e-6 3.3e-6 3.3e-6"/>
                              <joint name="finger_1_joint_3" axis="0 0 1" range="-1.2217 -0.0523"/>
                              <geom class="robotiq_visual" quat="0.96639 0 0 0.257081" type="mesh" mesh="rq_link_3"/>
                              <geom name="f1_tip" class="robotiq_fingertip" type="capsule" fromto="0 0 0  0.03 0 0" size="0.008"/>
                            </body>
                          </body>
                        </body>
                      </body>

                      <body name="finger_2_link_0" pos="-0.0455 0.0214 -0.036" quat="-2.59838e-06 0.706825 0.707388 2.59631e-06">
                        <inertial pos="0.02 0 0" mass="0.05" diaginertia="3.3e-6 3.3e-6 3.3e-6"/>
                        <joint name="palm_finger_2_joint" axis="0 1 0" range="-0.192 0.1784"/>
                        <geom class="robotiq_visual" pos="0.02 0 0" type="mesh" mesh="rq_link_0"/>
                        <body name="finger_2_link_1" pos="0.02 0 0">
                          <inertial pos="0.025 -0.014 0" mass="0.15" diaginertia="1.0e-5 3.6e-5 3.6e-5"/>
                          <joint name="finger_2_joint_1" axis="0 0 1" range="0.0495 1.2218"/>
                          <geom class="robotiq_visual" pos="0.05 -0.028 0" quat="0.96639 0 0 -0.257081" type="mesh" mesh="rq_link_1"/>
                          <body name="finger_2_link_2" pos="0.05 -0.028 0" quat="0.96639 0 0 -0.257081">
                            <inertial pos="0.02 0 0.0075" mass="0.15" diaginertia="1.0e-5 3.6e-5 3.6e-5"/>
                            <joint name="finger_2_joint_2" axis="0 0 1" range="0 1.5708"/>
                            <geom class="robotiq_visual" pos="0.039 0 0.0075" type="mesh" mesh="rq_link_2"/>
                            <body name="finger_2_link_3" pos="0.039 0 0">
                              <inertial pos="0.01 0 0" mass="0.05" diaginertia="3.3e-6 3.3e-6 3.3e-6"/>
                              <joint name="finger_2_joint_3" axis="0 0 1" range="-1.2217 -0.0523"/>
                              <geom class="robotiq_visual" quat="0.96639 0 0 0.257081" type="mesh" mesh="rq_link_3"/>
                              <geom name="f2_tip" class="robotiq_fingertip" type="capsule" fromto="0 0 0  0.03 0 0" size="0.008"/>
                            </body>
                          </body>
                        </body>
                      </body>

                      <body name="finger_middle_link_0" pos="0.0455 0.0214 0" quat="0.707388 0 0 0.706825">
                        <inertial pos="0.02 0 0" mass="0.05" diaginertia="3.3e-6 3.3e-6 3.3e-6"/>
                        <geom class="robotiq_visual" pos="0.02 0 0" type="mesh" mesh="rq_link_0"/>
                        <body name="finger_middle_link_1" pos="0.02 0 0">
                          <inertial pos="0.025 -0.014 0" mass="0.15" diaginertia="1.0e-5 3.6e-5 3.6e-5"/>
                          <joint name="finger_middle_joint_1" axis="0 0 1" range="0.0495 1.2218"/>
                          <geom class="robotiq_visual" pos="0.05 -0.028 0" quat="0.96639 0 0 -0.257081" type="mesh" mesh="rq_link_1"/>
                          <body name="finger_middle_link_2" pos="0.05 -0.028 0" quat="0.96639 0 0 -0.257081">
                            <inertial pos="0.02 0 0.0075" mass="0.15" diaginertia="1.0e-5 3.6e-5 3.6e-5"/>
                            <joint name="finger_middle_joint_2" axis="0 0 1" range="0 1.5708"/>
                            <geom class="robotiq_visual" pos="0.039 0 0.0075" type="mesh" mesh="rq_link_2"/>
                            <body name="finger_middle_link_3" pos="0.039 0 0">
                              <inertial pos="0.01 0 0" mass="0.05" diaginertia="3.3e-6 3.3e-6 3.3e-6"/>
                              <joint name="finger_middle_joint_3" axis="0 0 1" range="-1.2217 -0.0523"/>
                              <geom class="robotiq_visual" quat="0.96639 0 0 0.257081" type="mesh" mesh="rq_link_3"/>
                              <geom name="fm_tip" class="robotiq_fingertip" type="capsule" fromto="0 0 0  0.03 0 0" size="0.008"/>
                            </body>
                          </body>
                        </body>
                      </body>

                    </body>
                    <!-- ===== END GRIPPER ===== -->

                  </body>
                </body>
              </body>
            </body>
          </body>
        </body>
      </body>
    </body>
  </worldbody>

  <contact>
    <exclude body1="base" body2="link1"/>
    <exclude body1="base" body2="link2"/>
    <exclude body1="base" body2="link3"/>
    <exclude body1="link1" body2="link3"/>
    <exclude body1="link3" body2="link5"/>
    <exclude body1="link4" body2="link7"/>
    <exclude body1="link5" body2="link7"/>
  </contact>

  <actuator>
    <general name="actuator1" joint="joint1" class="joint1"/>
    <general name="actuator2" joint="joint2" class="joint2"/>
    <general name="actuator3" joint="joint3" class="joint1"/>
    <general name="actuator4" joint="joint4" class="joint2"/>
    <general name="actuator5" joint="joint5" class="joint1"/>
    <general name="actuator6" joint="joint6" class="joint2"/>
    <general name="actuator7" joint="joint7" class="joint3"/>

    <position name="f1_j1" class="robotiq" joint="finger_1_joint_1"      ctrlrange="0.05 1.22"/>
    <position name="f1_j2" class="robotiq" joint="finger_1_joint_2"      ctrlrange="0.0 1.57"/>
    <position name="f1_j3" class="robotiq" joint="finger_1_joint_3"      ctrlrange="-1.22 -0.05"/>
    <position name="f2_j1" class="robotiq" joint="finger_2_joint_1"      ctrlrange="0.05 1.22"/>
    <position name="f2_j2" class="robotiq" joint="finger_2_joint_2"      ctrlrange="0.0 1.57"/>
    <position name="f2_j3" class="robotiq" joint="finger_2_joint_3"      ctrlrange="-1.22 -0.05"/>
    <position name="fm_j1" class="robotiq" joint="finger_middle_joint_1" ctrlrange="0.05 1.22"/>
    <position name="fm_j2" class="robotiq" joint="finger_middle_joint_2" ctrlrange="0.0 1.57"/>
    <position name="fm_j3" class="robotiq" joint="finger_middle_joint_3" ctrlrange="-1.22 -0.05"/>
    <position name="pf1"   class="robotiq" joint="palm_finger_1_joint"   ctrlrange="-0.18 0.19"/>
    <position name="pf2"   class="robotiq" joint="palm_finger_2_joint"   ctrlrange="-0.19 0.18"/>
  </actuator>

  <keyframe>
    <!-- qpos: 7 IIWA + 11 gripper = 18 (no more palm freejoint!)
         ctrl: 7 IIWA + 11 gripper = 18 -->
    <key name="start"
         qpos="0 0.785398 0 -1.5708 0 0 0
               0 0.05 0 -0.05 0 0.05 0 -0.05 0.05 0 -0.05"
         ctrl="0 0.785398 0 -1.5708 0 0 0
               0.05 0 -0.05 0.05 0 -0.05 0.05 0 -0.05 0 0"/>
  </keyframe>
</mujoco>